Workbook

Sheet Inputs
A1: Input | B1: AAPL | C1: MSFT | D1: NVDA | E1: Definition / source note
A2: Ticker | B2: AAPL | C2: MSFT | D2: NVDA | E2: Example tickers
A3: Share price ($) | B3: 230 | C3: 510 | D3: 180 | E3: ILLUSTRATIVE PLACEHOLDERS; refresh from a current source
A4: Diluted shares (bn) | B4: 15.1 | C4: 7.43 | D4: 24.5 | E4: ILLUSTRATIVE; verify filings/provider
A5: Cash & short-term investments ($bn) | B5: 65 | C5: 80 | D5: 50 | E5: ILLUSTRATIVE
A6: Total debt ($bn) | B6: 100 | C6: 80 | D6: 10 | E6: ILLUSTRATIVE
A7: Revenue latest FY ($bn) | B7: 391 | C7: 281 | D7: 130 | E7: ILLUSTRATIVE
A8: EBIT margin | B8: 0.3 | C8: 0.45 | D8: 0.6 | E8: ILLUSTRATIVE
A9: Tax rate | B9: 0.16 | C9: 0.18 | D9: 0.15 | E9: Normalized effective tax rate
A10: D&A / revenue | B10: 0.03 | C10: 0.04 | D10: 0.02 | E10: Historical normalized assumption
A11: Capex / revenue | B11: 0.03 | C11: 0.04 | D11: 0.05 | E11: Use positive capex %
A12: Change in NWC / incremental revenue | B12: 0.01 | C12: 0.01 | D12: 0.02 | E12: Positive means cash investment
A13: Risk-free rate | B13: 0.042 | C13: 0.042 | D13: 0.042 | E13: Update from a current government yield
A14: Equity risk premium | B14: 0.05 | C14: 0.05 | D14: 0.05 | E14: Analyst assumption; document source
... A30: Forecast years | B30: 5 | C30: 5 | D30: 5 | E30: This workbook is set up for 5 explicit forecast years

Sheet WACC
A1: WACC component | B1: AAPL | C1: MSFT | D1: NVDA | E1: Method
A2: Cost of equity | B2: =Inputs!B13+Inputs!B14*Inputs!B15 | C2: =Inputs!C13+Inputs!C14*Inputs!C15 | D2: =Inputs!D13+Inputs!D14*Inputs!D15 | E2: CAPM = risk-free rate + beta × equity risk premium
A3: After-tax cost of debt | B3: =Inputs!B16*(1-Inputs!B9) | C3: =Inputs!C16*(1-Inputs!C9) | D3: =Inputs!D16*(1-Inputs!D9) | E3: Pre-tax debt cost × (1-tax rate)
A4: Debt weight | B4: =Inputs!B17 | C4: =Inputs!C17 | D4: =Inputs!D17 | E4: Market-value weight; equity weight = 1 - debt weight
A5: Equity weight | B5: =1-B4 | C5: =1-C4 | D5: =1-D4 | E5: 1 - debt weight
A6: Calculated WACC | B6: =B2*B5+B3*B4 | C6: =C2*C5+C3*C4 | D6: =D2*D5+D3*D4 | E6: Cost of equity × equity weight + after-tax debt cost × debt weight
A7: Selected WACC | B7: =IF(Inputs!B18>0,Inputs!B18,B6) | C7: =IF(Inputs!C18>0,Inputs!C18,C6) | D7: =IF(Inputs!D18>0,Inputs!D18,D6) | E7: Override if input override is non-zero

Sheet DCF
A1: Metric | B1: AAPL | C1: MSFT | D1: NVDA
A2: Year 0 Revenue ($bn) | B2: =Inputs!B7 | C2: =Inputs!C7 | D2: =Inputs!D7
A3: Year 1 Revenue | B3: =B2*(1+Inputs!B20) | C3: =C2*(1+Inputs!C20) | D3: =D2*(1+Inputs!D20)
A4: Year 2 Revenue | B4: =B3*(1+Inputs!B21) | C4: =C3*(1+Inputs!C21) | D4: =D3*(1+Inputs!D21)
A5: Year 3 Revenue | B5: =B4*(1+Inputs!B22) | C5: =C4*(1+Inputs!C22) | D5: =D4*(1+Inputs!D22)
A6: Year 4 Revenue | B6: =B5*(1+Inputs!B23) | C6: =C5*(1+Inputs!C23) | D6: =D5*(1+Inputs!D23)
A7: Year 5 Revenue | B7: =B6*(1+Inputs!B24) | C7: =C6*(1+Inputs!C24) | D7: =D6*(1+Inputs!D24)
A8: Year 1 EBIT | B8: =B3*Inputs!B25 | C8: =C3*Inputs!C25 | D8: =D3*Inputs!D25
A9: Year 2 EBIT | B9: =B4*Inputs!B26 | C9: =C4*Inputs!C26 | D9: =D4*Inputs!D26
A10: Year 3 EBIT | B10: =B5*Inputs!B27 | C10: =C5*Inputs!C27 | D10: =D5*Inputs!D27
A11: Year 4 EBIT | B11: =B6*Inputs!B28 | C11: =C6*Inputs!C28 | D11: =D6*Inputs!D28
A12: Year 5 EBIT | B12: =B7*Inputs!B29 | C12: =C7*Inputs!C29 | D12: =D7*Inputs!D29
A13: Year 1 NOPAT | B13: =B8*(1-Inputs!B9) | C13: =C8*(1-Inputs!C9) | D13: =D8*(1-Inputs!D9)
A14: Year 2 NOPAT | B14: =B9*(1-Inputs!B9) | C14: =C9*(1-Inputs!C9) | D14: =D9*(1-Inputs!D9)
A15: Year 3 NOPAT | B15: =B10*(1-Inputs!B9) | C15: =C10*(1-Inputs!C9) | D15: =D10*(1-Inputs!D9)
A16: Year 4 NOPAT | B16: =B11*(1-Inputs!B9) | C16: =C11*(1-Inputs!C9) | D16: =D11*(1-Inputs!D9)
A17: Year 5 NOPAT | B17: =B12*(1-Inputs!B9) | C17: =C12*(1-Inputs!C9) | D17: =D12*(1-Inputs!D9)
A18: Year 1 D&A | B18: =B3*Inputs!B10 | C18: =C3*Inputs!C10 | D18: =D3*Inputs!D10
A19: Year 2 D&A | B19: =B4*Inputs!B10 | C19: =C4*Inputs!C10 | D19: =D4*Inputs!D10
A20: Year 3 D&A | B20: =B5*Inputs!B10 | C20: =C5*Inputs!C10 | D20: =D5*Inputs!D10
A21: Year 4 D&A | B21: =B6*Inputs!B10 | C21: =C6*Inputs!C10 | D21: =D6*Inputs!D10
A22: Year 5 D&A | B22: =B7*Inputs!B10 | C22: =C7*Inputs!C10 | D22: =D7*Inputs!D10
A23: Year 1 Capex | B23: =B3*Inputs!B11 | C23: =C3*Inputs!C11 | D23: =D3*Inputs!D11
A24: Year 2 Capex | B24: =B4*Inputs!B11 | C24: =C4*Inputs!C11 | D24: =D4*Inputs!D11
A25: Year 3 Capex | B25: =B5*Inputs!B11 | C25: =C5*Inputs!C11 | D25: =D5*Inputs!D11
A26: Year 4 Capex | B26: =B6*Inputs!B11 | C26: =C6*Inputs!C11 | D26: =D6*Inputs!D11
A27: Year 5 Capex | B27: =B7*Inputs!B11 | C27: =C7*Inputs!C11 | D27: =D7*Inputs!D11
A28: Year 1 Change in NWC | B28: =(B3-B2)*Inputs!B12 | C28: =(C3-C2)*Inputs!C12 | D28: =(D3-D2)*Inputs!D12
A29: Year 2 Change in NWC | B29: =(B4-B3)*Inputs!B12 | C29: =(C4-C3)*Inputs!C12 | D29: =(D4-D3)*Inputs!D12
A30: Year 3 Change in NWC | B30: =(B5-B4)*Inputs!B12 | C30: =(C5-C4)*Inputs!C12 | D30: =(D5-D4)*Inputs!D12
A31: Year 4 Change in NWC | B31: =(B6-B5)*Inputs!B12 | C31: =(C6-C5)*Inputs!C12 | D31: =(D6-D5)*Inputs!D12
A32: Year 5 Change in NWC | B32: =(B7-B6)*Inputs!B12 | C32: =(C7-C6)*Inputs!C12 | D32: =(D7-D6)*Inputs!D12
A33: Year 1 FCFF | B33: =B13+B18-B23-B28 | C33: =C13+C18-C23-C28 | D33: =D13+D18-D23-D28
A34: Year 2 FCFF | B34: =B14+B19-B24-B29 | C34: =C14+C19-C24-C29 | D34: =D14+D19-D24-D29
A35: Year 3 FCFF | B35: =B15+B20-B25-B30 | C35: =C15+C20-C25-C30 | D35: =D15+D20-D25-D30
A36: Year 4 FCFF | B36: =B16+B21-B26-B31 | C36: =C16+C21-C26-C31 | D36: =D16+D21-D26-D31
A37: Year 5 FCFF | B37: =B17+B22-B27-B32 | C37: =C17+C22-C27-C32 | D37: =D17+D22-D27-D32
A38: PV explicit FCFF | B38: =B33/(1+WACC!B7)^1+B34/(1+WACC!B7)^2+B35/(1+WACC!B7)^3+B36/(1+WACC!B7)^4+B37/(1+WACC!B7)^5 | C38: =C33/(1+WACC!C7)^1+C34/(1+WACC!C7)^2+C35/(1+WACC!C7)^3+C36/(1+WACC!C7)^4+C37/(1+WACC!C7)^5 | D38: =D33/(1+WACC!D7)^1+D34/(1+WACC!D7)^2+D35/(1+WACC!D7)^3+D36/(1+WACC!D7)^4+D37/(1+WACC!D7)^5
A39: Terminal value | B39: =B37*(1+Inputs!B19)/(WACC!B7-Inputs!B19) | C39: =C37*(1+Inputs!C19)/(WACC!C7-Inputs!C19) | D39: =D37*(1+Inputs!D19)/(WACC!D7-Inputs!D19)
A40: PV terminal value | B40: =B39/(1+WACC!B7)^5 | C40: =C39/(1+WACC!C7)^5 | D40: =D39/(1+WACC!D7)^5
...

Sheet Scenarios
A1: Ticker | B1: Scenario | C1: Growth adjustment | D1: Margin adjustment | E1: WACC adjustment | F1: Terminal growth adjustment | G1: Python produces values
A2: AAPL | B2: Bear | C2: -0.05 | D2: -0.03 | E2: 0.01 | F2: -0.005 | G2: Run Python for scenario values
A3: AAPL | B3: Base | C3: 0 | D3: 0 | E3: 0 | F3: 0 | G3: Run Python for scenario values
A4: AAPL | B4: Bull | C4: 0.05 | D4: 0.03 | E4: -0.01 | F4: 0.005 | G4: Run Python for scenario values
A5: MSFT | B5: Bear | C5: -0.05 | D5: -0.03 | E5: 0.01 | F5: -0.005 | G5: Run Python for scenario values
A6: MSFT | B6: Base | C6: 0 | D6: 0 | E6: 0 | F6: 0 | G6: Run Python for scenario values
A7: MSFT | B7: Bull | C7: 0.05 | D7: 0.03 | E7: -0.01 | F7: 0.005 | G7: Run Python for scenario values
A8: NVDA | B8: Bear | C8: -0.05 | D8: -0.03 | E8: 0.01 | F8: -0.005 | G8: Run Python for scenario values
A9: NVDA | B9: Base | C9: 0 | D9: 0 | E9: 0 | F9: 0 | G9: Run Python for scenario values
A10: NVDA | B10: Bull | C10: 0.05 | D10: 0.03 | E10: -0.01 | F10: 0.005 | G10: Run Python for scenario values

Sheet Checks
A1: Validation | B1: AAPL | C1: MSFT | D1: NVDA | E1: Expected
A2: WACC > terminal growth | B2: =IF(WACC!B7>Inputs!B19,"PASS","FAIL") | C2: =IF(WACC!C7>Inputs!C19,"PASS","FAIL") | D2: =IF(WACC!D7>Inputs!D19,"PASS","FAIL") | E2: PASS
A3: Positive shares | B3: =IF(Inputs!B4>0,"PASS","FAIL") | C3: =IF(Inputs!C4>0,"PASS","FAIL") | D3: =IF(Inputs!D4>0,"PASS","FAIL") | E3: PASS
A4: Positive revenue | B4: =IF(Inputs!B7>0,"PASS","FAIL") | C4: =IF(Inputs!C7>0,"PASS","FAIL") | D4: =IF(Inputs!D7>0,"PASS","FAIL") | E4: PASS
A5: Nonnegative capex ratio | B5: =IF(Inputs!B11>=0,"PASS","FAIL") | C5: =IF(Inputs!C11>=0,"PASS","FAIL") | D5: =IF(Inputs!D11>=0,"PASS","FAIL") | E5: PASS
A6: Terminal value share of EV | B6: =IF(DCF!B46<0.85,"REVIEW","HIGH DEPENDENCE") | C6: =IF(DCF!C46<0.85,"REVIEW","HIGH DEPENDENCE") | D6: =IF(DCF!D46<0.85,"REVIEW","HIGH DEPENDENCE") | E6: Review if >85%

Sheet Read Me
A1: Reverse DCF Complete Project | B1: Instructions
A2: Purpose | B2: End-to-end learning project for equity valuation and investment research.
A3: Important | B3: Yellow inputs are illustrative placeholders, not verified live market data. Replace them before interpreting valuation.
A4: Workflow | B4: 1. Verify financial inputs. 2. Review WACC. 3. Reconcile DCF. 4. Run Python for implied expectations, scenarios, Monte Carlo, peer analysis and memos.
A5: FCFF | B5: FCFF = EBIT × (1 − tax rate) + D&A − capex − change in NWC.
A6: WACC | B6: CAPM cost of equity + after-tax cost of debt weighted by capital structure. Beta, risk-free rate, ERP, debt cost and weights require sourcing.
A7: Python outputs | B7: Run script to create valuation CSVs, peer comparisons, source metadata, distribution/tornado charts and one-page memos.
A8: Limitations | B8: Data providers may have missing or inconsistent fields. Confirm against annual/quarterly filings. Monte Carlo probability depends on analyst assumptions.
A9: Excel reverse solver | B9: The Python version solves implied growth and margin. Excel includes Goal Seek as a manual alternative: set intrinsic value/share to share price by changing a growth or margin input.
A10: Version | B10: Version 2 (2026-10-14): Python adds valuation bridge diagnostics, terminal-value concentration, raw provider statement exports, peer multiple proxies, explicit review-required flags, deterministic seed, and run-failure log.
A11: Validation status | B11: Python unit tests pass in the build environment. Live market data retrieval has not been run here because yfinance is not installed and live outputs are not verified.
A12: Important | B12: Excel is a manual model: no live data pull or Python reverse solver is embedded. Reconcile assumptions and results before use.

Sheet Source Log
A1: Company | B1: Metric | C1: Value | D1: Units | E1: Source URL / document | F1: Fiscal period / as-of | G1: Retrieved UTC | H1: Analyst check | I1: Notes
A2: AAPL | H2: Pending verification
A3: AAPL | H3: Pending verification
A4: AAPL | H4: Pending verification
A5: AAPL | H5: Pending verification
A6: AAPL | H6: Pending verification
A7: AAPL | H7: Pending verification
A8: AAPL | H8: Pending verification
A9: MSFT | H9: Pending verification
A10: MSFT | H10: Pending verification
A11: MSFT | H11: Pending verification
A12: MSFT | H12: Pending verification
A13: MSFT | H13: Pending verification
... A21: NVDA | H21: Pending verification

Sheet Peer Sets
A1: Target ticker | B1: Peer ticker | C1: Reason for comparability | D1: Include? | E1: Review notes
A2: AAPL | B2: MSFT | C2: Large-cap platform / device ecosystem; not a perfect peer | D2: Review | E2: Consider hardware, services and ecosystem mix
A3: AAPL | B3: DELL | C3: Hardware exposure; different business model | D3: Review | E3: Do not use without segment and margin context
A4: AAPL | B4: HPQ | C4: Hardware exposure; different growth profile | D4: Review | E4: Potentially useful only for selected metrics
A5: MSFT | B5: GOOGL | C5: Large-cap software / cloud / platform | D5: Review | E5: Business mix differs materially
A6: MSFT | B6: ORCL | C6: Enterprise software / cloud | D6: Review | E6: Compare recurring revenue and margins
A7: MSFT | B7: AMZN | C7: Cloud overlap; retail mix distorts consolidated margins | D7: Review | E7: Use segment-level AWS comparison if possible
A8: NVDA | B8: AMD | C8: Semiconductor / accelerator competition | D8: Review | E8: Compare growth, gross margins, capex and cycles
A9: NVDA | B9: AVGO | C9: Semiconductor / infrastructure exposure | D9: Review | E9: Business mix differs; explain adjustments
A10: NVDA | B10: QCOM | C10: Semiconductor company; different end markets | D10: Review | E10: May be a weak peer for AI accelerators

Sheet Historical Data
A1: Ticker | B1: Fiscal year | C1: Revenue | D1: Revenue growth | E1: EBIT | F1: EBIT margin | G1: FCF | H1: FCF margin | I1: Capex | J1: D&A | K1: Source URL | L1: Analyst notes
L2: Populate from annual reports; do not treat blanks as zero.
L3: Populate from annual reports; do not treat blanks as zero.
L4: Populate from annual reports; do not treat blanks as zero.
L5: Populate from annual reports; do not treat blanks as zero.
L6: Populate from annual reports; do not treat blanks as zero.
L7: Populate from annual reports; do not treat blanks as zero.
L8: Populate from annual reports; do not treat blanks as zero.
L9: Populate from annual reports; do not treat blanks as zero.
L10: Populate from annual reports; do not treat blanks as zero.
L11: Populate from annual reports; do not treat blanks as zero.
L12: Populate from annual reports; do not treat blanks as zero.
L13: Populate from annual reports; do not treat blanks as zero.
... L19: Populate from annual reports; do not treat blanks as zero.

Sheet Scenario Analysis
A1: Ticker | B1: Scenario | C1: Revenue growth | D1: EBIT margin | E1: WACC | F1: Terminal growth | G1: Fair value/share | H1: Upside/downside | I1: Narrative / evidence
A2: AAPL | B2: Bear | I2: Fill with model output and document evidence
A3: AAPL | B3: Base | I3: Fill with model output and document evidence
A4: AAPL | B4: Bull | I4: Fill with model output and document evidence
A5: MSFT | B5: Bear | I5: Fill with model output and document evidence
A6: MSFT | B6: Base | I6: Fill with model output and document evidence
A7: MSFT | B7: Bull | I7: Fill with model output and document evidence
A8: NVDA | B8: Bear | I8: Fill with model output and document evidence
A9: NVDA | B9: Base | I9: Fill with model output and document evidence
A10: NVDA | B10: Bull | I10: Fill with model output and document evidence

Sheet Model Governance
A1: Control | B1: Required standard | C1: Status | D1: Evidence / action
A2: Data timestamp | B2: Every market and financial input has as-of date and source | C2: Pending | D2: Complete Source Log
A3: Units / currency | B3: All inputs reconciled to USD bn and USD/share, or converted explicitly | C3: Pending | D3: Check each provider field
A4: Fiscal period | B4: Financial statement values all refer to matching fiscal periods | C4: Pending | D4: Check annual vs quarterly and restatements
A5: Diluted shares | B5: Shares used are diluted and appropriate for valuation date | C5: Pending | D5: Review filing / provider
A6: Debt and leases | B6: Debt definition consistent; state whether leases included | C6: Pending | D6: Document policy
A7: Stock-based compensation | B7: Consider dilution and whether SBC is reflected consistently in cash flow | C7: Pending | D7: Add dilution schedule if material
A8: WACC | B8: Risk-free rate, beta, ERP, cost of debt and weights sourced | C8: Pending | D8: Document sources and dates
A9: Terminal value | B9: WACC > terminal growth; TV/EV ratio reviewed | C9: Pending | D9: Run sensitivities
A10: Reverse solver | B10: Implied growth/margin is bracketed and has a valid solution | C10: Pending | D10: Report no solution when none exists
A11: Peer set | B11: Each peer has a business-model rationale | C11: Pending | D11: Review Peer Sets tab
A12: One-offs | B12: Normalize restructuring, impairments, unusual tax and working capital | C12: Pending | D12: Reconcile annual filings
... A14: Memo sign-off | B14: Investment conclusion includes risks and evidence against thesis | C14: Pending | D14: Complete one-page memo
A15: Live data pipeline | B15: Not validated in build environment | C15: Install requirements; run AAPL/MSFT/NVDA; inspect raw statements and source metadata.
A16: Python unit tests | B16: PASS: 9 tests | C16: Re-run python -m unittest -v after changes.
A17: Peer multiples | B17: Proxy only | C17: Verify EV bridge and peer comparability against filings/market data.
